Workbook

Sheet Cover
D3: Technical - Tool
D4: Gas Pipeline
D5: API 1102 Highway Loading
B8: HDR Engineering Inc. | D8: Approved By: | F8: Rev 0
B9: Best Practice | F9: Issue Date: | G9: 45665
C10: Author: | D10: Barry Brookins | F10: Owner: | G10: Barry Brookins
B13: Revision History
B14: Rev | C14: Description of Change | G14: Effective Date
D15: Originator | E15: Checker | F15: Reviewer
B16: 0 | C16: Initial Release | D16: Barry B. | E16: Holly E. | G16: 45665
B17: 1
B22: For questions regarding this Spreadsheet contact
B24: Barry Brookins
B25: HDR Engineering Inc. - Rosemont, IL
B26: barry.brookins@hdrinc.com
B28: or
B30: Jon Liechti
B31: HDR Engineering Inc. - Tulsa, OK
B32: 918.281.4330
B33: Jonathan.Liechti@hdrinc.com

Sheet Approval

Sheet Instructions
A1: Conventions for this spreadsheet
A2: Convention | B2: Meaning
A3: Black on White | B3: Formulas or Constants (Not to be updated)
A4: Black on Yellow | B4: Data Entry (Overwrites) - Unprotected Cell

Sheet Contents
B2: Table of Contents
B4: SHEET | C4: Contents
B5: Cover | C5: Best Practice approval and contact information
A6: 1 | B6: Instructions | C6: Spreadsheet Instructions
A7: =1+A6 -> 2 | B7: Contents | C7: Table of Contents
A8: =1+A7 -> 3 | B8: Info | C8: User Information
A9: =1+A8 -> 4 | B9: Highway Loading | C9: API 1102 Highway Loading Analysis
A10: =1+A9 -> 5 | B10: Hand Calcs | C10: QC Hand-Calc
A11: =1+A10 -> 6 | B11: Tables | C11: Tables used for dropdowns and VLOOKUP's within the calculation tab
A12: =1+A11 -> 7 | B12: Sources | C12: Sources used for calculations
A13: =1+A12 -> 8
A14: =1+A13 -> 9
A15: =1+A14 -> 10
A16: =1+A15 -> 11
A17: =1+A16 -> 12
A18: =1+A17 -> 13
A19: =1+A18 -> 14
A20: =1+A19 -> 15
A21: =1+A20 -> 16
A22: =1+A21 -> 17
A23: =1+A22 -> 18
A24: =1+A23 -> 19
... A29: =1+A28 -> 24

Sheet Info
A1: ReadMe
A3: 1 PURPOSE
A4: The purpose of this procedure is to check the combined stress of a pipeline due to internal pipeline pressure and external highway loading.
A6: 2 DEFINITIONS
A9: 3 PROCEDURES
A10: The stresses due to internal and external highway loads on a pipeline is determined by first acquiring the allowable and actual Barlow stress, and the circumferntial stress due to the earth load. Then the cyclic circumferential and longitudinal stresses are calculated, followed by the circumferential stress due to internal pressurization. Next, the max circumferential, longitudinal, and radial stresses are calculated. Finally, the actual and allowable effective, girth, and longitudinal stresses are calculated.
A11: 3.1 Calculate the Hoop Stress (Barlow):
A12: Hoop Stress (Barlow) = Pressure * Pipe Diameter / (2 * Wall Thickness)
A13: 3.2 Calculate the Allowable Hoop Stress:
A14: Allowable Hoop Stress = Design Factor * Longitudinal Joint Factor * Temperature Derating Factor * SMYS
A15: 3.3 Calculate the Circumferential Stress from Earth Load:
A16: Circumferential Stress from Earth Load = Stiffness Factor for Earth Load Circumferential Stress * Burial Factor for Earth Load Circumferential Stress * Excavation Factor for Earth Load Circumferential Stress * Average Unit Weight of Soil * Pipe Diameter
... A49: For conditions outside these ranges, consult API RP 1102 directly.

Sheet Highway Loading
A1: API 1102 Highway Loading
A3: Purpose | B3: The purpose of this procedure is to check the combined stress of a pipeline due to internal pipeline pressure and external highway loading.
A5: Find | B5: Description | C5: Variable | D5: Unit | E5: Comment
B6: Barlow Stress | C6: SHi | D6: psi
B7: Effective Stress | C7: Seff | D7: psi
B8: Girth Weld Stress | C8: SLh | D8: psi
B9: Long. Weld Stress | C9: SHh | D9: psi
A11: Given | B11: Description | C11: Value | D11: Unit | E11: Comment
B12: Pipe Diameter | C12: 12 | D12: in
B13: D - Pipe Outside Diameter | C13: =IF(ISBLANK($C$12)=TRUE,"",HLOOKUP($C$12,'Highway Loading'!$C$155:$AD$156,2,FALSE)) -> 12.75 | D13: in
B14: tw - Wall Thickness | C14: 0.25 | D14: in
B15: Pipe Specification | C15: API 5L
B16: Pipe Grade | C16: X65
B17: SMYS | C17: =IF(ISBLANK($C$16)=TRUE,"",INDEX('Highway Loading'!$C$216:$AG$216,MATCH($C$16,'Highway Loading'!$C$215:$AG$215,0))) -> 65000 | D17: psi
B18: Pipeline Location | C18: Pipelines, mains, and service lines
B19: Class Location | C19: 1
B20: F - Design Factor | C20: =INDEX('Highway Loading'!I245:L253,MATCH(C18,'Highway Loading'!H245:H253,0),MATCH(C19,'Highway Loading'!I244:L244,0)) -> 0.72
B21: Pipe Class | C21: Electric Resistance Welded
B22: E - Longitudinal Joint Factor | C22: =IF(ISBLANK($C$21),"",IF(OR($C$21="SEAMLESS",$C$21="ELECTRIC RESISTANCE WELDED",$C$21="SUBMERGED ARC WELDED",$C$21="COMBINATION WELDED"),1,IF($C$21="FURNACE BUTT WELDED",0.6,IF($C$21="ELECTRIC FUSION WELDED, EVEN CLASS",1,IF($C$21="ELECTRIC FUSION WELDED, ODD CLASS",0.8,IF($C$13>4.5,0.8,0.6)))))) -> 1
B23: Pipe Material | C23: Steel
B24: Es - Young's Modulus | C24: =(VLOOKUP(C23,'Highway Loading'!B283:E292,2, FALSE)) -> 29000000 | D24: psi | E24: =_xlfn.CONCAT("Typically ", (VLOOKUP(C23,'Highway Loading'!B283:E292,2, FALSE)), " psi") -> Typically 29000000 psi
B25: v - Poisson's Ratio | C25: =(VLOOKUP(C23,'Highway Loading'!B283:E292,3, FALSE)) -> 0.3
B26: α - Coefficient of thermal expansion | C26: =(VLOOKUP(C23,'Highway Loading'!B283:E292,4, FALSE)) -> 6.5e-06 | D26: 1/°F
B27: T2 - Operating Temperature | C27: 70 | D27: °F | E27: Recommended Temp. Range: -20°F to 450°F
B28: T - Temperature Derating Factor | C28: =IF(C27>250, 1-(1/30/50*(C27-250)), 1) -> 1
B29: P - Operating Pressure | C29: 1000 | D29: psi | E29: Allowable Range: 0 to 6000
B30: Soil Type | C30: Loose sands and gravels
B31: E' - Modulus of Soil Reaction | C31: =VLOOKUP(C30, 'Highway Loading'!B256:D261,2, FALSE) -> 500 | D31: psi
B32: Er - Resilient Modulus | C32: =VLOOKUP(C30, 'Highway Loading'!B256:D261,3, FALSE) -> 10000 | D32: psi
B33: γ - Average Unit Weight of Soil | C33: 120 | D33: lb/ft3 | E33: Typically equal to 120 PCF. Allowable range: 50-200
B34: H - Pipe Depth | C34: 6 | D34: ft | E34: Allowable Range: 1 to 30
B35: Bd - Bored Diameter | C35: 14.75 | D35: inch | E35: Equal to D+2 if pipe is proposed or within 10 years of installation Equal to D+1 if pipe is within 10-20 years of installation Equal to D if pipe was installed greater than 20 years ago
B36: Pavement Type | C36: Flexible
B37: Critical Configuration | C37: Tandem Axle | E37: Cricitical case is tandem axle unless: no pavement, H < 4 ft., and D <= 12 in.
B38: Design Wheel Load | C38: =(VLOOKUP(C37,'Highway Loading'!B340:C341,2,FALSE)) -> 10000 | D38: lbs
B39: T1 - Installation Temperature | C39: 70 | D39: °F | E39: Allowed Temp. Range: -20°F to 450°F
A41: Equations | B41: Hoop Stress (Barlow) = Pressure * Pipe Diameter / (2 * Wall Thickness) Allowable Hoop Stress = Design Factor * Longitudinal Joint Factor * Temperature Derating Factor * SMYS Circumferential Stress from Earth Load = Stiffness Factor for Earth Load Circumferential Stress * Burial Factor for Earth Load Circumferential Stress * Excavation Factor for Earth Load Circumferential Stress * Average Unit Weight of Soil * Pipe Diameter Highway Cyclic Circumferential Stress = Highway Stiffness Factor for Cyclic Circumferential Stress * Highway Geometry Factor for Cyclic Circumferential Stress * Highway Pavement Type Factor * Axle Configuration Factor * Impact Factor * Design Wheel Load Highway Cyclic Longitudinal Stress = Highway Stiffness Factor for Cyclic Longitudinal Stress * Highway Geometry Factor for Cyclic Longitudinal Stress * Highway Pavement Type Factor * Axle Configuration Factor * Impact Factor * Design Wheel Load Circumferential Stress Due to Internal Pressurization = Pressure * (Pipe Diameter - Wall Thickness) / (2 * Wall Thickness) Maximum Circumferential Stress = Circumferential Stress from Earth Load + Highway Cyclic Circumferential Stress + Circumferential Stress Due to Internal Pressurization Maximum Longitudinal Stress = Highway Cyclic Longitudinal Stress - Young's Modulus * Coeffient of Thermal Expansion * (Installation Temp - Operating Temp) + Poisson's Ratio * (Circumferential Stress from Earth Load + Circumferential Stress Due to Internal Pressurization) Maximum Radial Stress Result = -1 * Pressure Total Effective Stress = Sqrt(1/2 * (Maximum Circumferential Stress - Maximum Longitudinal Stress)^2 + (Maximum Longitudinal Stress - Maximum Radial Stress)^2 + (Maximum Radial Stress - Maximum Circumferential Stress)^2) Allowable Effective Stress = SMYS * Design Factor Allowable Stress of Girth Welds = Fatigue Resistance of Girth Welds * Design Factor Allowable Stress of Longitudinal Welds = Fatigue Resistance of Longitudinal Welds * Design Factor
A43: Calculations | B43: Description | C43: Value | D43: Unit | E43: Comment
B44: Shi(Barlow) - Hoop Stress | C44: =C29*C13/(2*C14) -> 25500 | D44: psi
B45: Allowable Hoop Stress | C45: =C20*C22*C28*C17 -> 46800 | D45: psi
...

Sheet Hand Calcs
A1: Pipe and Operational Characteristics
A2: Pipe Diameter | B2: ='Highway Loading'!C12 -> 12 | C2: in
A3: D - Pipe Outside Diameter | B3: ='Highway Loading'!C13 -> 12.75 | C3: in
A4: tw - Wall Thickness | B4: ='Highway Loading'!C14 -> 0.25 | C4: in
A5: SMYS | B5: ='Highway Loading'!C17 -> 65000 | C5: psi
A6: Design Class Location | B6: ='Highway Loading'!C19 -> 1 | G6: 2 Minimum For RR crossings
A7: F - Design Factor | B7: ='Highway Loading'!C20 -> 0.72
A8: Pipe Class | B8: ='Highway Loading'!C21 -> Electric Resistance Welded
A9: E - Longitudinal Joint Factor | B9: ='Highway Loading'!C22 -> 1
A10: Pipe Material | B10: ='Highway Loading'!C23 -> Steel
A11: Es - Young's Modulus | B11: ='Highway Loading'!C24 -> 29000000 | C11: psi | G11: Typically | H11: =(VLOOKUP(B10,'Highway Loading'!B283:E292,2, FALSE)) -> 29000000
A12: v - Poisson's Ratio | B12: ='Highway Loading'!C25 -> 0.3
A13: α - Coefficient of thermal expansion | B13: ='Highway Loading'!C26 -> 6.5e-06 | C13: 1/°F
A14: T - Temperature Derating Factor | B14: ='Highway Loading'!C28 -> 1 | G14: Typically equal to 1 near ambient temperature
A15: T2 - Operating Temperature | B15: ='Highway Loading'!C27 -> 70 | C15: °F
A16: P - Operating Pressure | B16: ='Highway Loading'!C29 -> 1000 | C16: psi
A18: Installation and Site Characteristics
A19: Soil Type | B19: ='Highway Loading'!C30 -> Loose sands and gravels
A20: E' - Modulus of Soil Reaction | B20: ='Highway Loading'!C31 -> 500 | C20: psi
A21: Er - Resilient Modulus | B21: ='Highway Loading'!C32 -> 10000 | C21: psi
A22: γ - Average Unit Weight of Soil | B22: ='Highway Loading'!C33 -> 120 | C22: lb/ft3 | G22: Typically equal to 120 PCF
A23: H - Pipe Depth | B23: ='Highway Loading'!C34 -> 6 | C23: ft
A24: Bd - Bored Diameter | B24: ='Highway Loading'!C35 -> 14.75 | C24: inch | G24: Typically equal to D+2
A25: Pavement Type | B25: ='Highway Loading'!C36 -> Flexible
A26: Critical Configuration | B26: ='Highway Loading'!C37 -> Tandem Axle | G26: Typically Tandem Axle
A27: Design Wheel Load | B27: ='Highway Loading'!C38 -> 10000 | C27: lbs
A28: T1 - Installation Temperature | B28: ='Highway Loading'!C39 -> 70 | C28: °F
A30: Result | B30: Spreadsheet Calculation | D30: Hand Calc Formulas | E30: Hand Calc Results | G30: Source
A31: Shi(Barlow) - Hoop Stress | B31: ='Highway Loading'!C44 -> 25500 | C31: psi | D31: =ROUND(B16*B3/(2*B4),2)&" = "&B16&"*"&B3&"/(2*"&B4&")" -> 25500 = 1000*12.75/(2*0.25) | E31: =B16*B3/(2*B4) -> 25500
A32: Allowable Hoop Stress | B32: ='Highway Loading'!C45 -> 46800 | C32: psi | D32: =ROUND(B7*B9*B14*B5,2)&" = "&B7&"*"&B9&"*"&B14&"*"&B5 -> 46800 = 0.72*1*1*65000 | E32: =B7*B9*B14*B5 -> 46800
L33: Stiffness Factor - Earth Load
A34: Khe - Stiffness Factor for Earth Load Circumferential Stress | B34: ='Highway Loading'!C47 -> 2790.5294 | G34: Refer To "Stiffness Factor - Earth Load" Chart | L34: Data
A35: Be - Burial Factor for Earth Load Circumferential Stress | B35: ='Highway Loading'!C48 -> 1.0658475 | G35: Refer To "Burial Factor - Earth Load" Chart | L35: {=F80:H83} -> E' | M35: 500 | N35: psi
A36: Ee - Excavation Factor for Earth Load Circumferential Stress | B36: ='Highway Loading'!C49 -> 1.1041078 | G36: Refer To "Excavation Factor - Earth Load" Chart | L36: tw/D | M36: 0.019607843
A37: SHe - Circumferential Stress from Earth Load | B37: ='Highway Loading'!C50 -> 2907.6414 | C37: psi | D37: =ROUND(B37,2)&" = "&ROUND(B34,2)&"*"&ROUND(B35,3)&"*"&ROUND(B36,3)&"*("&B22&"/1728)*"&B3 -> 2907.64 = 2790.53*1.066*1.104*(120/1728)*12.75 | E37: =B34*B35*B36*(B22/12^3)*B3 -> 2907.6414
A39: Fi - Impact Factor | B39: ='Highway Loading'!C52 -> 1.4762195 | G39: Refer To "Impact Factor" Chart | L39: =VLOOKUP(L33,Tables!A2:B12,2, FALSE) -> #VALUE!
A41: KHh - Highway Stiffness Factor for Cyclic Circumferential Stress | B41: ='Highway Loading'!C54 -> 14.207908 | G41: Refer To "Stiffness Factor - Circum." Chart
A42: GHh - Highway Geometry Factor for Cyclic Circumferential Stress | B42: ='Highway Loading'!C55 -> 1.01675 | G42: Refer To "Geometry Factor - Circum." Chart
A43: R - Highway Pavement Type Factor | B43: ='Highway Loading'!C56 -> 1 | G43: Refer To "Pavement and Axle Type" Chart
A44: L - Axle Configuration Factor | B44: ='Highway Loading'!C57 -> 1 | G44: Refer To "Pavement and Axle Type" Chart
...

Sheet Tables
A1: Charts
A2: Stiffness Factor - Earth Load | B2: #VALUE!
A3: Burial Factor - Earth Load | B3: #VALUE!
A4: Excavation Factor - Earth Load | B4: #VALUE!
A5: Impact Factor | B5: #VALUE!
A6: Stiffness Factor - Circum. | B6: #VALUE!
A7: Geometry Factor - Circum. | B7: #VALUE!
A8: Pavement and Axle Type | B8: #VALUE!
A9: Stiffness Factor - Long. | B9: #VALUE!
A10: Geometry Factor - Long. | B10: #VALUE!
A11: Fatigue Endurance Limits | B11: #VALUE!
A14: Stiffness Factor for Earth Load Circumferential Stress
A15: E = .2 ksi | C15: E = .5 ksi | E15: E = 1 ksi | G15: E = 2 ksi
A16: X (tw/D) | B16: Y (Khe) | C16: X (tw/D) | D16: Y (Khe) | E16: X (tw/D) | F16: Y (Khe) | G16: X (tw/D) | H16: Y (Khe)
A17: 0 | B17: 11632 | C17: 0 | D17: 7625 | E17: 0 | F17: 5772 | G17: 0 | H17: 4443
A18: 0.00726 | B18: 11632 | C18: 0.00726 | D18: 7625 | E18: 0.00738 | F18: 5772 | G18: 0.00726 | H18: 4443
A19: 0.00811 | B19: 11632 | C19: 0.00792 | D19: 7625 | E19: 0.00775 | F19: 5449 | G19: 0.00775 | H19: 4000
A20: 0.00825 | B20: 11338 | C20: 0.00825 | D20: 7286 | E20: 0.00825 | F20: 5175 | G20: 0.00825 | H20: 3804
A21: 0.01 | B21: 8552 | C21: 0.01 | D21: 6280 | E21: 0.01 | F21: 4499 | G21: 0.01 | H21: 3208
A22: 0.0125 | B22: 6564 | C22: 0.0125 | D22: 5374 | E22: 0.0125 | F22: 3882 | G22: 0.0125 | H22: 2777
A23: 0.015 | B23: 4873 | C23: 0.015 | D23: 4305 | E23: 0.015 | F23: 3261 | G23: 0.015 | H23: 2404
A24: 0.0175 | B24: 3900 | C24: 0.0175 | D24: 3476 | E24: 0.0175 | F24: 2791 | G24: 0.0175 | H24: 2145
A25: 0.02 | B25: 3000 | C25: 0.02 | D25: 2663 | E25: 0.02 | F25: 2292 | G25: 0.02 | H25: 1852
A26: 0.025 | B26: 1781 | C26: 0.025 | D26: 1642 | E26: 0.025 | F26: 1545 | G26: 0.025 | H26: 1387
A27: 0.03 | B27: 1153 | C27: 0.03 | D27: 1077 | E27: 0.03 | F27: 1066 | G27: 0.03 | H27: 1000
A28: 0.035 | B28: 819 | C28: 0.035 | D28: 819 | E28: 0.035 | F28: 819 | G28: 0.035 | H28: 819
... A38: 5 | B38: 88 | C38: 5 | D38: 88 | E38: 5 | F38: 88 | G38: 5 | H38: 88
A40: Burial Factor Earth Load
A41: Type A | C41: Type B
A42: X (H/Bd) | B42: Y (Be) | C42: X (H/Bd) | D42: Y (Be)
A43: 0 | B43: 0 | C43: 0 | D43: 0
A44: 1 | B44: 0.321 | C44: 1 | D44: 0.321
A45: 2 | B45: 0.644 | C45: 2 | D45: 0.631
A46: 3 | B46: 0.844 | C46: 3 | D46: 0.776
A47: 4 | B47: 0.983 | C47: 4 | D47: 0.893
A48: 5 | B48: 1.077 | C48: 5 | D48: 0.964
A49: 6 | B49: 1.162 | C49: 6 | D49: 1.032
A50: 7 | B50: 1.215 | C50: 7 | D50: 1.071
A51: 8 | B51: 1.26 | C51: 8 | D51: 1.108
A52: 9 | B52: 1.295 | C52: 9 | D52: 1.133
...

Sheet Sources
A1: Sources and References
A3: Reference | B3: Description
A4: 49 CFR Part 192 Subpart C | B4: Pipe Design - Federal pipeline safety regulations
A57: PE Mechanical Reference Handbook | B57: NCEES reference for mechanical PE exam
A93: API RP 1102, 7th Ed. (2007, R2022) Steel Pipelines Crossing Railroads and Highways
