Workbook

Sheet Cover
D3: Technical - Tool
D4: Gas Pipeline
D5: API1102 Railroad Loading
B8: HDR Engineering Inc. | D8: Approved By: | F8: Rev 0
B9: Best Practice | F9: Issue Date: | G9: 45665
C10: Author: | D10: Barry Brookins | F10: Owner: | G10: Barry Brookins
B13: Revision History
B14: Rev | C14: Description of Change | G14: Effective Date
D15: Originator | E15: Checker | F15: Reviewer
B16: 0 | C16: Initial Release | D16: Barry B. | E16: Holly E. | G16: 45665
B17: 1
B22: For questions regarding this Spreadsheet contact
B24: Barry Brookins
B25: HDR Engineering Inc. - Rosemont, IL
B26: barry.brookins@hdrinc.com
B28: or
B30: Jon Liechti
B31: HDR Engineering Inc. - Tulsa, OK
B32: 918.281.4330
B33: Jonathan.Liechti@hdrinc.com

Sheet Approval

Sheet Instructions
A1: Conventions for this spreadsheet
A2: Convention | B2: Meaning
A3: Black on White | B3: Formulas or Constants (Not to be updated)
A4: Black on Yellow | B4: Data Entry (Overwrites) - Unprotected Cell

Sheet Contents
B2: Table of Contents
B4: SHEET | C4: Contents
B5: Cover | C5: Best Practice approval and contact information
A6: 1 | B6: Instructions | C6: Spreadsheet Instructions
A7: =1+A6 -> 2 | B7: Contents | C7: Table of Contents
A8: =1+A7 -> 3 | B8: Info | C8: User Information
A9: =1+A8 -> 4 | B9: Design Pressure | C9: API 1102 Railroad Loading Calculations
A10: =1+A9 -> 5 | B10: Hand Calcs | C10: API 1102 Railroad Loading QC Hand-Calc
A11: =1+A10 -> 6 | B11: Tables | C11: Tables used for dropdowns and VLOOKUP's within the calculation tab
A12: =1+A11 -> 7 | B12: Sources | C12: Sources used for calculations
A13: =1+A12 -> 8
A14: =1+A13 -> 9
A15: =1+A14 -> 10
A16: =1+A15 -> 11
A17: =1+A16 -> 12
A18: =1+A17 -> 13
A19: =1+A18 -> 14
A20: =1+A19 -> 15
A21: =1+A20 -> 16
A22: =1+A21 -> 17
A23: =1+A22 -> 18
A24: =1+A23 -> 19
... A29: =1+A28 -> 24

Sheet Info
A1: ReadMe
A3: 1 PURPOSE
A4: The purpose of this procedure is to check the combined stress of a pipeline due to internal pipeline pressure and external railroad loading.
A6: 2 DEFINITIONS
A9: 3 PROCEDURES
A10: The stresses due to internal and external highway loads on a pipeline are determined by first acquiring the allowable and actual Barlow stress, and the circumferential stress due to the earth load. Then the cyclic circumferential and longitudinal stresses are calculated, followed by the circumferential stress due to internal pressurization. Next, the max circumferential, longitudinal, and radial stresses are calculated. Finally, the actual and allowable effective, girth, and longitudinal stresses are calculated.
A11: 3.1 Calculate the Hoop Stress (Barlow):
A12: Hoop Stress (Barlow) = Pressure * Pipe Diameter / (2 * Wall Thickness)
A13: 3.2 Calculate the Allowable Hoop Stress:
A14: Allowable Hoop Stress = Design Factor * Longitudinal Joint Factor * Temperature Derating Factor * SMYS
A15: 3.3 Calculate the Circumferential Stress from Earth Load:
A16: Circumferential Stress from Earth Load = Stiffness Factor for Earth Load Circumferential Stress * Burial Factor for Earth Load Circumferential Stress * Excavation Factor for Earth Load Circumferential Stress * Average Unit Weight of Soil * Pipe Diameter
... A50: For conditions outside these ranges, consult API RP 1102 directly.

Sheet Railroad Loading
A1: API 1102 Railroad Loading
A3: Purpose | B3: The purpose of this procedure is to check the combined stress of a pipeline due to internal pipeline pressure and external railroad loading.
A5: Find | B5: Description | C5: Variable | D5: Unit | E5: Comment
B6: Barlow Stress | C6: SHi | D6: psi
B7: Effective Stress | C7: Seff | D7: psi
B8: Girth Weld Stress | C8: SLh | D8: psi
B9: Long. Weld Stress | C9: SHh | D9: psi
A11: Given | B11: Description | C11: Value | D11: Unit | E11: Comment
B12: Pipe Diameter | C12: 12 | D12: in
B13: D - Pipe Outside Diameter | C13: =IFERROR(VLOOKUP(C12, 'Railroad Loading'!B312:C347, 2, FALSE), C12) -> 12.75 | D13: in
B14: tw - Wall Thickness | C14: 0.25 | D14: in
B15: Pipe Specification | C15: API 5L
B16: Pipe Grade | C16: X42
B17: SMYS | C17: =IF(ISBLANK($C$16)=TRUE,"",INDEX('Railroad Loading'!$C$232:$AG$232,MATCH($C$16,'Railroad Loading'!$C$231:$AG$231,0))) -> 42000 | D17: psi
B18: Pipeline Location | C18: Pipelines, mains, and service lines
B19: Design Class Location | C19: 1 | E19: 2 Minimum For RR crossings
B20: F - Design Factor | C20: =INDEX('Railroad Loading'!I261:L269,MATCH(C18,'Railroad Loading'!H261:H269,0),MATCH(C19,'Railroad Loading'!I260:L260,0)) -> 0.72
B21: Pipe Class | C21: Electric Resistance Welded
B22: E - Longitudinal Joint Factor | C22: =IF(ISBLANK($C$21),"",IF(OR($C$21="SEAMLESS",$C$21="ELECTRIC RESISTANCE WELDED",$C$21="SUBMERGED ARC WELDED",$C$21="COMBINATION WELDED"),1,IF($C$21="FURNACE BUTT WELDED",0.6,IF($C$21="ELECTRIC FUSION WELDED, EVEN CLASS",1,IF($C$21="ELECTRIC FUSION WELDED, ODD CLASS",0.8,IF($C$13>4.5,0.8,0.6)))))) -> 1
B23: Pipe Material | C23: Steel
B24: Es - Young's Modulus | C24: =(VLOOKUP(C23,'Railroad Loading'!B299:E308,2, FALSE)) -> 29000000 | D24: psi | E24: =_xlfn.CONCAT("Typically ", (VLOOKUP(C23,'Railroad Loading'!B299:E308,2, FALSE)), " psi") -> Typically 29000000 psi
B25: v - Poisson's Ratio | C25: =(VLOOKUP(C23,'Railroad Loading'!B299:E308,3, FALSE)) -> 0.3
B26: α - Coefficient of thermal expansion | C26: =(VLOOKUP(C23,'Railroad Loading'!B299:E308,4, FALSE)) -> 6.5e-06 | D26: 1/°F
B27: T2 - Operating Temperature | C27: 70 | D27: °F | E27: Recommended Temp. Range: -20°F to 450°F
B28: T - Temperature Derating Factor | C28: =IF(C27>250, 1-(1/30/50*(C27-250)), 1) -> 1 | E28: Typically equal to 1 near ambient temperature
B29: P - Operating Pressure | C29: 800 | D29: psi | E29: Allowable Range: 0 to 6000
B30: Soil Type | C30: Soft to medium clays and silts with high plasticities
B31: E' - Modulus of Soil Reaction | C31: =VLOOKUP(C30, 'Railroad Loading'!B272:D277,2, FALSE) -> 200 | D31: psi
B32: Er - Resilient Modulus | C32: =VLOOKUP(C30, 'Railroad Loading'!B272:D277,3, FALSE) -> 5000 | D32: psi
B33: γ - Average Unit Weight of Soil | C33: 120 | D33: lb/ft3 | E33: Typically equal to 120 PCF. Allowable range: 50-200
B34: H - Pipe Depth | C34: 6 | D34: ft | E34: Allowable Range: 1 to 30
B35: Bd - Bored Diameter | C35: 14.75 | D35: inch | E35: Equal to D+2 if pipe is proposed or within 10 years of installation Equal to D+1 if pipe is within 10-20 years of installation Equal to D if pipe was installed greater than 20 years ago
B36: T1 - Installation Temperature | C36: 70 | D36: °F | E36: Allowed Temp. Range: -20°F to 450°F
B37: Number of Tracks | C37: 2 | E37: Allowable values: 1 or 2
B38: w - Applied Design Surface Pressure | C38: 13.9 | D38: psi | E38: Typically equal to 13.9 per API 1102. Allowable values: 0-100
A40: Equations | B40: Hoop Stress (Barlow) = Pressure * Pipe Diameter / (2 * Wall Thickness) Allowable Hoop Stress = Design Factor * Longitudinal Joint Factor * Temperature Derating Factor * SMYS Circumferential Stress from Earth Load = Stiffness Factor for Earth Load Circumferential Stress * Burial Factor for Earth Load Circumferential Stress * Excavation Factor for Earth Load Circumferential Stress * Average Unit Weight of Soil * Pipe Diameter Railroad Cyclic Circumferential Stress = Railroad Stiffness Factor for Cyclic Circumferential Stress * Railroad Geometry Factor for Cyclic Circumferential Stress * Railroad Double Track Factor for Circumferential Stress * Impact Factor * Applied Design Surface Pressure Railroad Cyclic Longitudinal Stress = Railroad Stiffness Factor for Cyclic Longitudinal Stress * Railroad Geometry Factor for Cyclic Longitudinal Stress * Railroad Double Track Factor for Longitudinal Stress * Impact Factor * Applied Design Surface Pressure Circumferential Stress Due to Internal Pressurization = Pressure * (Pipe Diameter - Wall Thickness) / (2 * Wall Thickness) Maximum Circumferential Stress = Circumferential Stress from Earth Load + Railroad Cyclic Circumferential Stress + Circumferential Stress Due to Internal Pressurization Maximum Longitudinal Stress = Railroad Cyclic Longitudinal Stress - Young's Modulus * Coeffient of Thermal Expansion * (Installation Temp - Operating Temp) + Poisson's Ratio * (Circumferential Stress from Earth Load + Circumferential Stress Due to Internal Pressurization) Maximum Radial Stress Result = -1 * Pressure Total Effective Stress = Sqrt(1/2 * (Maximum Circumferential Stress - Maximum Longitudinal Stress)^2 + (Maximum Longitudinal Stress - Maximum Radial Stress)^2 + (Maximum Radial Stress - Maximum Circumferential Stress)^2) Allowable Effective Stress = SMYS * Design Factor Allowable Stress of Girth Welds = Fatigue Resistance of Girth Welds * Design Factor Allowable Stress of Longitudinal Welds = Fatigue Resistance of Longitudinal Welds * Design Factor
A42: Calculations | B42: Description | C42: Value | D42: Unit | E42: Comment
B43: Shi(Barlow) - Hoop Stress | C43: =C29*C13/(2*C14) -> 20400 | D43: psi
B44: Allowable Hoop Stress | C44: =C20*C22*C28*C17 -> 30240 | D44: psi
B46: Khe - Stiffness Factor for Earth Load Circumferential Stress | C46: =VLOOKUP(C31, N92:O95, 2, FALSE) -> 3141.1765
...

Sheet Hand Calcs
A1: Inputs
A2: Pipe Diameter | B2: 12 | C2: in
A3: D - Pipe Outside Diameter | B3: =IFERROR(VLOOKUP(B2, 'Railroad Loading'!B312:C347, 2, FALSE), B2) -> 12.75 | C3: in
A4: tw - Wall Thickness | B4: 0.25 | C4: in
A5: SMYS | B5: 42000 | C5: psi
A6: Design Class Location | B6: 1
A7: F - Design Factor | B7: =VLOOKUP(B6,'Railroad Loading'!B280:C283,2, FALSE) -> 0.72
A8: Pipe Class | B8: Electric Resistance Welded
A9: E - Longitudinal Joint Factor | B9: =VLOOKUP(B8,'Railroad Loading'!B287:C294,2, FALSE) -> 1
A10: Pipe Material | B10: Steel
A11: Es - Young's Modulus | B11: 30000000 | C11: psi
A12: v - Poisson's Ratio | B12: =(VLOOKUP(B10,'Railroad Loading'!B299:E308,3, FALSE)) -> 0.3
A13: α - Coefficient of thermal expansion | B13: =(VLOOKUP(B10,'Railroad Loading'!B299:E308,4, FALSE)) -> 6.5e-06 | C13: 1/°F
A14: T - Temperature Derating Factor | B14: 1 | G14: Typically equal to 1 near ambient temperature
A15: T2 - Operating Temperature | B15: 70 | C15: °F
A16: P - Operating Pressure | B16: 800 | C16: psi
A17: Soil Type | B17: Soft to medium clays and silts with high plasticities
A18: E' - Modulus of Soil Reaction | B18: =VLOOKUP(B17, 'Railroad Loading'!B272:D277,2, FALSE) -> 200 | C18: psi
A19: Er - Resilient Modulus | B19: =VLOOKUP(B17, 'Railroad Loading'!B272:D277,3, FALSE) -> 5000 | C19: psi
A20: γ - Average Unit Weight of Soil | B20: 120 | C20: lb/ft3 | G20: Typically equal to 120 PCF
A21: H - Pipe Depth | B21: 6 | C21: ft
A22: Bd - Bored Diameter | B22: 14.8 | C22: inch | G22: Typically equal to D+2
A23: T1 - Installation Temperature | B23: 70 | C23: °F
A24: Number of Tracks | B24: 2
A25: w - Applied Design Surface Pressure | B25: 13.9 | C25: psi | G25: Typically equal to 13.9
A27: Result | B27: Spreadsheet Calculation | D27: Hand Calc Formulas | E27: Hand Calc Results | G27: Source
A28: Shi(Barlow) - Hoop Stress | B28: ='Railroad Loading'!C43 -> 20400 | C28: psi | D28: =ROUND(B16*B3/(2*B4),2)&" = "&B16&"*"&B3&"/(2*"&B4&")" -> 20400 = 800*12.75/(2*0.25) | E28: =B16*B3/(2*B4) -> 20400
A29: Allowable Hoop Stress | B29: ='Railroad Loading'!C44 -> 30240 | C29: psi | D29: =ROUND(B7*B9*B14*B5,2)&" = "&B7&"*"&B9&"*"&B14&"*"&B5 -> 30240 = 0.72*1*1*42000 | E29: =B7*B9*B14*B5 -> 30240
M30: Burial Factor - Earth Load
A31: Khe - Stiffness Factor for Earth Load Circumferential Stress | B31: ='Railroad Loading'!C46 -> 3141.1765 | G31: Refer To "Stiffness Factor - Earth Load" Chart | M31: Data
A32: Be - Burial Factor for Earth Load Circumferential Stress | B32: ='Railroad Loading'!C47 -> 1.0658475 | G32: Refer To "Burial Factor - Earth Load" Chart | M32: {=F84:G85} -> H/Bd
A33: Ee - Excavation Factor for Earth Load Circumferential Stress | B33: ='Railroad Loading'!C48 -> 1.1041078 | G33: Refer To "Excavation Factor - Earth Load" Chart
A34: SHe - Circumferential Stress from Earth Load | B34: ='Railroad Loading'!C49 -> 3273.0043 | C34: psi | D34: =ROUND(B31*B32*B33*(B20/12^3)*B3,2)&" = "&ROUND(B31,2)&"*"&ROUND(B32,2)&"*"&ROUND(B33,2)&"*("&B20&"/12^3)*"&B3 -> 3273 = 3141.18*1.07*1.1*(120/12^3)*12.75 | E34: =B31*B32*B33*(B20/12^3)*B3 -> 3273.0043 | M34: =VLOOKUP(M30,Tables!A2:B12,2, FALSE) -> #VALUE!
A36: Fi - Impact Factor | B36: ='Railroad Loading'!C51 -> 1.7263923 | G36: Refer To "Impact Factor" Chart
A38: Nh - Railroad Double Track Factor for Circumferential Stress | B38: ='Railroad Loading'!C53 -> 1.1398775 | G38: Refer To "Railroad Track Factor - Circum." Chart
A39: KHr - Railroad Stiffness Factor for Cyclic Circumferential Stress | B39: ='Railroad Loading'!C54 -> 441.03809 | G39: Refer To "Stiffness Factor - Circum." Chart
A40: GHr - Railroad Geometry Factor for Cyclic Circumferential Stress | B40: ='Railroad Loading'!C55 -> 0.98525 | G40: Refer To "Geometry Factor - Circum." Chart
A41: SHr - Railroad Cyclic Circumferential Stress | B41: ='Railroad Loading'!C56 -> 11885.98 | C41: psi | D41: =ROUND(B39*B40*B38*B36*B25,2)&" = "&ROUND(B39,2)&"*"&ROUND(B40,2)&"*"&ROUND(B38,2)&"*"&ROUND(B36,2)&"*"&B25 -> 11885.98 = 441.04*0.99*1.14*1.73*13.9 | E41: =B39*B40*B38*B36*B25 -> 11885.98
A42: NL - Railroad Double Track Factor Longitudinal Stress | B42: ='Railroad Loading'!C57 -> 1.0207291 | G42: Refer To "Railroad Track Factor - Long." Chart
A43: KLr - Railroad Stiffness Factor Cyclic Longitudinal Stress | B43: ='Railroad Loading'!C58 -> 464.98039 | G43: Refer To "Stiffness Factor - Long." Chart
...

Sheet Tables
A1: Charts
A2: Stiffness Factor - Earth Load | B2: #VALUE!
A3: Burial Factor - Earth Load | B3: #VALUE!
A4: Excavation Factor - Earth Load | B4: #VALUE!
A5: Impact Factor | B5: #VALUE!
A6: Railroad Track Factor - Circum. | B6: #VALUE!
A7: Stiffness Factor - Circum. | B7: #VALUE!
A8: Geometry Factor - Circum. | B8: #VALUE!
A9: Railroad Track Factor - Long. | B9: #VALUE!
A10: Stiffness Factor - Long. | B10: #VALUE!
A11: Geometry Factor - Long. | B11: #VALUE!
A12: Fatigue Endurance Limits | B12: #VALUE!
A15: Stiffness Factor for Earth Load Circumferential Stress
A16: E = .2 ksi | C16: E = .5 ksi | E16: E = 1 ksi | G16: E = 2 ksi
A17: X (tw/D) | B17: Y (Khe) | C17: X (tw/D) | D17: Y (Khe) | E17: X (tw/D) | F17: Y (Khe) | G17: X (tw/D) | H17: Y (Khe)
A18: 0 | B18: 11632 | C18: 0 | D18: 7625 | E18: 0 | F18: 5772 | G18: 0 | H18: 4443
A19: 0.00726 | B19: 11632 | C19: 0.00726 | D19: 7625 | E19: 0.00738 | F19: 5772 | G19: 0.00726 | H19: 4443
A20: 0.00811 | B20: 11632 | C20: 0.00792 | D20: 7625 | E20: 0.00775 | F20: 5449 | G20: 0.00775 | H20: 4000
A21: 0.00825 | B21: 11338 | C21: 0.00825 | D21: 7286 | E21: 0.00825 | F21: 5175 | G21: 0.00825 | H21: 3804
A22: 0.01 | B22: 8552 | C22: 0.01 | D22: 6280 | E22: 0.01 | F22: 4499 | G22: 0.01 | H22: 3208
A23: 0.0125 | B23: 6564 | C23: 0.0125 | D23: 5374 | E23: 0.0125 | F23: 3882 | G23: 0.0125 | H23: 2777
A24: 0.015 | B24: 4873 | C24: 0.015 | D24: 4305 | E24: 0.015 | F24: 3261 | G24: 0.015 | H24: 2404
A25: 0.0175 | B25: 3900 | C25: 0.0175 | D25: 3476 | E25: 0.0175 | F25: 2791 | G25: 0.0175 | H25: 2145
A26: 0.02 | B26: 3000 | C26: 0.02 | D26: 2663 | E26: 0.02 | F26: 2292 | G26: 0.02 | H26: 1852
A27: 0.025 | B27: 1781 | C27: 0.025 | D27: 1642 | E27: 0.025 | F27: 1545 | G27: 0.025 | H27: 1387
A28: 0.03 | B28: 1153 | C28: 0.03 | D28: 1077 | E28: 0.03 | F28: 1066 | G28: 0.03 | H28: 1000
A29: 0.035 | B29: 819 | C29: 0.035 | D29: 819 | E29: 0.035 | F29: 819 | G29: 0.035 | H29: 819
... A39: 5 | B39: 88 | C39: 5 | D39: 88 | E39: 5 | F39: 88 | G39: 5 | H39: 88
A41: Burial Factor Earth Load
A42: Type A | C42: Type B
A43: X (H/Bd) | B43: Y (Be) | C43: X (H/Bd) | D43: Y (Be)
A44: 0 | B44: 0 | C44: 0 | D44: 0
A45: 1 | B45: 0.321 | C45: 1 | D45: 0.321
A46: 2 | B46: 0.644 | C46: 2 | D46: 0.631
A47: 3 | B47: 0.844 | C47: 3 | D47: 0.776
A48: 4 | B48: 0.983 | C48: 4 | D48: 0.893
A49: 5 | B49: 1.077 | C49: 5 | D49: 0.964
A50: 6 | B50: 1.162 | C50: 6 | D50: 1.032
A51: 7 | B51: 1.215 | C51: 7 | D51: 1.071
A52: 8 | B52: 1.26 | C52: 8 | D52: 1.108
...

Sheet Sources
A4: eCFR :: 49 CFR Part 192 Subpart C -- Pipe Design
A57: PE Mechanical Reference Handbook
A93: API Recommended Practice 1102, Seventh Edition, December 2007, Reaffirmed June 2024
